I1010 07:18:17.987158       1 flags.go:64] FLAG: --allow-metric-labels="[]"
I1010 07:18:17.987244       1 flags.go:64] FLAG: --allow-metric-labels-manifest=""
I1010 07:18:17.987250       1 flags.go:64] FLAG: --authentication-kubeconfig=""
I1010 07:18:17.987252       1 flags.go:64] FLAG: --authentication-skip-lookup="false"
I1010 07:18:17.987255       1 flags.go:64] FLAG: --authentication-token-webhook-cache-ttl="10s"
I1010 07:18:17.987259       1 flags.go:64] FLAG: --authentication-tolerate-lookup-failure="true"
I1010 07:18:17.987261       1 flags.go:64] FLAG: --authorization-always-allow-paths="[/healthz,/readyz,/livez]"
I1010 07:18:17.987268       1 flags.go:64] FLAG: --authorization-kubeconfig=""
I1010 07:18:17.987270       1 flags.go:64] FLAG: --authorization-webhook-cache-authorized-ttl="10s"
I1010 07:18:17.987272       1 flags.go:64] FLAG: --authorization-webhook-cache-unauthorized-ttl="10s"
I1010 07:18:17.987274       1 flags.go:64] FLAG: --bind-address="0.0.0.0"
I1010 07:18:17.987276       1 flags.go:64] FLAG: --cert-dir=""
I1010 07:18:17.987278       1 flags.go:64] FLAG: --client-ca-file=""
I1010 07:18:17.987280       1 flags.go:64] FLAG: --config="/etc/kubernetes/scheduler-config.yaml"
I1010 07:18:17.987282       1 flags.go:64] FLAG: --contention-profiling="true"
I1010 07:18:17.987284       1 flags.go:64] FLAG: --disabled-metrics="[]"
I1010 07:18:17.987287       1 flags.go:64] FLAG: --feature-gates=""
I1010 07:18:17.987291       1 flags.go:64] FLAG: --help="false"
I1010 07:18:17.987293       1 flags.go:64] FLAG: --http2-max-streams-per-connection="0"
I1010 07:18:17.987295       1 flags.go:64] FLAG: --kube-api-burst="100"
I1010 07:18:17.987298       1 flags.go:64] FLAG: --kube-api-content-type="application/vnd.kubernetes.protobuf"
I1010 07:18:17.987300       1 flags.go:64] FLAG: --kube-api-qps="50"
I1010 07:18:17.987303       1 flags.go:64] FLAG: --kubeconfig=""
I1010 07:18:17.987305       1 flags.go:64] FLAG: --leader-elect="true"
I1010 07:18:17.987307       1 flags.go:64] FLAG: --leader-elect-lease-duration="15s"
I1010 07:18:17.987310       1 flags.go:64] FLAG: --leader-elect-renew-deadline="10s"
I1010 07:18:17.987311       1 flags.go:64] FLAG: --leader-elect-resource-lock="leases"
I1010 07:18:17.987313       1 flags.go:64] FLAG: --leader-elect-resource-name="kube-scheduler"
I1010 07:18:17.987315       1 flags.go:64] FLAG: --leader-elect-resource-namespace="kube-system"
I1010 07:18:17.987317       1 flags.go:64] FLAG: --leader-elect-retry-period="2s"
I1010 07:18:17.987319       1 flags.go:64] FLAG: --log-flush-frequency="5s"
I1010 07:18:17.987321       1 flags.go:64] FLAG: --log-text-info-buffer-size="0"
I1010 07:18:17.987351       1 flags.go:64] FLAG: --log-text-split-stream="false"
I1010 07:18:17.987356       1 flags.go:64] FLAG: --logging-format="text"
I1010 07:18:17.987358       1 flags.go:64] FLAG: --master=""
I1010 07:18:17.987360       1 flags.go:64] FLAG: --permit-address-sharing="false"
I1010 07:18:17.987365       1 flags.go:64] FLAG: --permit-port-sharing="false"
I1010 07:18:17.987367       1 flags.go:64] FLAG: --pod-max-in-unschedulable-pods-duration="5m0s"
I1010 07:18:17.987370       1 flags.go:64] FLAG: --profiling="true"
I1010 07:18:17.987371       1 flags.go:64] FLAG: --requestheader-allowed-names="[]"
I1010 07:18:17.987382       1 flags.go:64] FLAG: --requestheader-client-ca-file=""
I1010 07:18:17.987384       1 flags.go:64] FLAG: --requestheader-extra-headers-prefix="[x-remote-extra-]"
I1010 07:18:17.987390       1 flags.go:64] FLAG: --requestheader-group-headers="[x-remote-group]"
I1010 07:18:17.987395       1 flags.go:64] FLAG: --requestheader-username-headers="[x-remote-user]"
I1010 07:18:17.987419       1 flags.go:64] FLAG: --secure-port="10259"
I1010 07:18:17.987425       1 flags.go:64] FLAG: --show-hidden-metrics-for-version=""
I1010 07:18:17.987428       1 flags.go:64] FLAG: --tls-cert-file=""
I1010 07:18:17.987431       1 flags.go:64] FLAG: --tls-cipher-suites="[]"
I1010 07:18:17.987437       1 flags.go:64] FLAG: --tls-min-version=""
I1010 07:18:17.987439       1 flags.go:64] FLAG: --tls-private-key-file=""
I1010 07:18:17.987441       1 flags.go:64] FLAG: --tls-sni-cert-key="[]"
I1010 07:18:17.987462       1 flags.go:64] FLAG: --v="1"
I1010 07:18:17.987467       1 flags.go:64] FLAG: --version="false"
I1010 07:18:17.987474       1 flags.go:64] FLAG: --vmodule=""
I1010 07:18:17.987477       1 flags.go:64] FLAG: --write-config-to=""
I1010 07:18:18.259970       1 serving.go:380] Generated self-signed cert in-memory
W1010 07:18:18.260573       1 client_config.go:659] Neither --kubeconfig nor --master was specified.  Using the inClusterConfig.  This might not work.
I1010 07:18:18.834619       1 topologyscheduler.go:234] "TopologyScheduling: Initializing plugin"
I1010 07:18:18.835448       1 server.go:154] "Starting Kubernetes Scheduler" version="v0.0.20241010"
I1010 07:18:18.835480       1 server.go:156] "Golang settings" GOGC="" GOMAXPROCS="" GOTRACEBACK=""
I1010 07:18:18.839044       1 requestheader_controller.go:169] Starting RequestHeaderAuthRequestController
I1010 07:18:18.839091       1 shared_informer.go:313] Waiting for caches to sync for RequestHeaderAuthRequestController
I1010 07:18:18.839122       1 secure_serving.go:213] Serving securely on [::]:10259
I1010 07:18:18.839154       1 configmap_cafile_content.go:202] "Starting controller" name="client-ca::kube-system::extension-apiserver-authentication::requestheader-client-ca-file"
I1010 07:18:18.839166       1 shared_informer.go:313] Waiting for caches to sync for client-ca::kube-system::extension-apiserver-authentication::requestheader-client-ca-file
I1010 07:18:18.839157       1 configmap_cafile_content.go:202] "Starting controller" name="client-ca::kube-system::extension-apiserver-authentication::client-ca-file"
I1010 07:18:18.839178       1 shared_informer.go:313] Waiting for caches to sync for client-ca::kube-system::extension-apiserver-authentication::client-ca-file
I1010 07:18:18.839181       1 tlsconfig.go:240] "Starting DynamicServingCertificateController"
I1010 07:18:18.939918       1 shared_informer.go:320] Caches are synced for client-ca::kube-system::extension-apiserver-authentication::requestheader-client-ca-file
I1010 07:18:18.939927       1 shared_informer.go:320] Caches are synced for RequestHeaderAuthRequestController
I1010 07:18:18.939955       1 shared_informer.go:320] Caches are synced for client-ca::kube-system::extension-apiserver-authentication::client-ca-file
I1010 07:18:28.324513       1 topologyscheduler.go:113] "TopologyScheduling: PreFilter: got CRD Info" spec=[{"resource":"top-layer","dependencies":[{"resource":"mid-layer","bandwidth":{"requests":250,"limits":50},"latency":{"requests":5,"limits":15}}]},{"resource":"mid-layer","dependencies":[{"resource":"bottom-layer","bandwidth":{"requests":200,"limits":100},"latency":{"requests":10,"limits":15}}]},{"resource":"bottom-layer"}] status=[{"Resource":"bottom-layer","Order":1,"Phase":"Not scheduled","SchedulingInfo":null},{"Resource":"mid-layer","Order":2,"Phase":"Not scheduled","SchedulingInfo":null},{"Resource":"top-layer","Order":3,"Phase":"Not scheduled","SchedulingInfo":null}]
I1010 07:18:28.324966       1 topologyscheduler.go:133] "TopologyScheduling: PreFilter: get Node used" node="kind-worker" allocatable=1
I1010 07:18:28.325096       1 topologyscheduler.go:133] "TopologyScheduling: PreFilter: get Node used" node="kind-worker2" allocatable=1
I1010 07:18:28.325143       1 topologyscheduler.go:133] "TopologyScheduling: PreFilter: get Node used" node="kind-worker3" allocatable=1
I1010 07:18:28.325169       1 topologyscheduler.go:133] "TopologyScheduling: PreFilter: get Node used" node="kind-worker4" allocatable=1
I1010 07:18:28.379500       1 topologyscheduler.go:38] "TopologyScheduling: QueueSort called" pod1="deploy3-54d8599cb5-7z7rb" pod2="deploy2-745cd94cfc-lrqs6"
I1010 07:18:28.379632       1 topologyscheduler.go:51] "TopologyScheduling: QueueSort: Pods have resource label" pod1="deploy3-54d8599cb5-7z7rb" Resource1="top-layer" pod2="deploy2-745cd94cfc-lrqs6" Resource2="mid-layer"
I1010 07:18:28.379426       1 topologyscheduler.go:145] "TopologyScheduling: PreFilter: got network metrics" data={"Bandwidth":{"kind-worker":{"kind-worker2":120.5,"kind-worker3":115.3,"kind-worker4":110.8},"kind-worker2":{"kind-worker":120.5,"kind-worker3":130.7,"kind-worker4":125.4},"kind-worker3":{"kind-worker":115.3,"kind-worker2":130.7,"kind-worker4":118.9},"kind-worker4":{"kind-worker":110.8,"kind-worker2":125.4,"kind-worker3":118.9}},"Latency":{"kind-worker":{"kind-worker2":10.3,"kind-worker3":11.5,"kind-worker4":9.8},"kind-worker2":{"kind-worker":10.3,"kind-worker3":12.1,"kind-worker4":11.2},"kind-worker3":{"kind-worker":11.5,"kind-worker2":12.1,"kind-worker4":10.9},"kind-worker4":{"kind-worker":9.8,"kind-worker2":11.2,"kind-worker3":10.9}}}
I1010 07:18:28.380235       1 topologyscheduler.go:162] "TopologyScheduling: PreFilter: get dependencies" resourceList=["bottom-layer","mid-layer","top-layer"] dependencies=[[100,200,15,10],[50,250,15,5]]
I1010 07:18:28.380304       1 topologyscheduler.go:165] "TopologyScheduling: PreFilter: got best node set" nodeSet=["kind-worker","kind-worker3","kind-worker4"] bestScore=-2995.25
I1010 07:18:28.430558       1 topologyscheduler.go:73] "TopologyScheduling: QueueSort: Got order level" order1=3 order2=2
I1010 07:18:28.430683       1 topologyscheduler.go:181] "TopologyScheduler: Filter called" pod="deploy1-7bf65ddf-ztbqf" node="kind-worker4"
I1010 07:18:28.430707       1 topologyscheduler.go:181] "TopologyScheduler: Filter called" pod="deploy1-7bf65ddf-ztbqf" node="kind-worker"
I1010 07:18:28.430719       1 topologyscheduler.go:181] "TopologyScheduler: Filter called" pod="deploy1-7bf65ddf-ztbqf" node="kind-worker3"
I1010 07:18:28.430732       1 topologyscheduler.go:181] "TopologyScheduler: Filter called" pod="deploy1-7bf65ddf-ztbqf" node="kind-worker2"
I1010 07:18:33.431164       1 topologyscheduler.go:221] error reading "PreFilterState" from cyclestate: <nil>, Waiting...
I1010 07:18:33.431219       1 topologyscheduler.go:221] error reading "PreFilterState" from cyclestate: <nil>, Waiting...
I1010 07:18:33.431225       1 topologyscheduler.go:221] error reading "PreFilterState" from cyclestate: <nil>, Waiting...
I1010 07:18:33.431251       1 topologyscheduler.go:221] error reading "PreFilterState" from cyclestate: <nil>, Waiting...
I1010 07:18:38.432071       1 topologyscheduler.go:221] error reading "PreFilterState" from cyclestate: <nil>, Waiting...
I1010 07:18:38.432104       1 topologyscheduler.go:221] error reading "PreFilterState" from cyclestate: <nil>, Waiting...
I1010 07:18:38.432123       1 topologyscheduler.go:221] error reading "PreFilterState" from cyclestate: <nil>, Waiting...
I1010 07:18:38.432094       1 topologyscheduler.go:221] error reading "PreFilterState" from cyclestate: <nil>, Waiting...
I1010 07:18:43.432883       1 topologyscheduler.go:221] error reading "PreFilterState" from cyclestate: <nil>, Waiting...
I1010 07:18:43.432939       1 topologyscheduler.go:221] error reading "PreFilterState" from cyclestate: <nil>, Waiting...
I1010 07:18:43.432917       1 topologyscheduler.go:221] error reading "PreFilterState" from cyclestate: <nil>, Waiting...
I1010 07:18:43.432969       1 topologyscheduler.go:221] error reading "PreFilterState" from cyclestate: <nil>, Waiting...
I1010 07:18:48.331500       1 topologyscheduler.go:221] error reading "PreFilterState" from cyclestate: <nil>, Waiting...
I1010 07:18:48.331519       1 topologyscheduler.go:221] error reading "PreFilterState" from cyclestate: <nil>, Waiting...
I1010 07:18:48.331530       1 topologyscheduler.go:221] error reading "PreFilterState" from cyclestate: <nil>, Waiting...
I1010 07:18:48.331540       1 topologyscheduler.go:221] error reading "PreFilterState" from cyclestate: <nil>, Waiting...
